Workbook

Sheet co2 emissions
A1: CO2 Emissions
A2: 8529 | B2: mean | C2: =AVERAGE(A2:A2692) -> 114169.46
A3: 8529 | B3: trim mean | C3: =TRIMMEAN(A2:A2692,0.1) -> 38217.111
A4: 8236 | B4: median | C4: =MEDIAN(A2:A2692) -> 8529
A5: 6524 | B5: st dev | C5: =STDEV(A2:A2692) -> 550017.64
A6: 3927
A7: 1991
A8: 1016
A9: 583
A10: 781
A11: 1338
A12: 733
A13: 645
A14: 359
A15: 8529
A16: 8529
A17: 4283
... A2692: 13887

Sheet gdpcapita vs leading interest
A1: GDP/CAPITA | B1: Lending Interest
A2: 3 | B2: 0.148 | C2: =CORREL(A2:A2692,B2:B2692) -> -0.15540669
A3: 115.31251 | B3: 0.148
A4: 185.95929 | B4: 0.148
A5: 198.2878 | B5: 0.148
A6: 220.05629 | B6: 0.148
A7: 252.40789 | B7: 0.148
A8: 275.35094 | B8: 0.18
A9: 373.59142 | B9: 0.181
A10: 376.97767 | B10: 0.149
A11: 450.65924 | B11: 0.15
A12: 561.19762 | B12: 0.157
A13: 613.97919 | B13: 0.151
A14: 687.58137 | B14: 0.15
... A2692: 908.78232 | B2692: 0.148

Sheet GDPCapita Vs BusinessTaxRate & 
A1: GDP/CAPITA | B1: Business Tax Rate | C1: Ease of Business
A2: 3 | B2: 0.489 | C2: 94 | D2: =CORREL(A2:A2692,C2:C2692) -> -0.15115818
A3: 115.31251 | B3: 0.489 | C3: 94
A4: 185.95929 | B4: 0.489 | C4: 94
A5: 198.2878 | B5: 0.489 | C5: 94
A6: 220.05629 | B6: 0.489 | C6: 94
A7: 252.40789 | B7: 0.363 | C7: 94
A8: 275.35094 | B8: 0.363 | C8: 94
A9: 373.59142 | B9: 0.363 | C9: 94
A10: 376.97767 | B10: 0.363 | C10: 94
A11: 450.65924 | B11: 0.363 | C11: 94
A12: 561.19762 | B12: 0.363 | C12: 94
A13: 613.97919 | B13: 0.363 | C13: 94
A14: 687.58137 | B14: 0.363 | C14: 170
... A2692: 908.78232 | B2692: 0.345 | C2692: 168

Sheet gdpcapita and tourism inbound
A1: GDP/CAPITA | B1: Tourism Inbound
A2: 3 | B2: 680000000 | C2: correlation | D2: =CORREL(A2:A2692,B2:B2692) -> 0.29236657
A3: 115.31251 | B3: 680000000
A4: 185.95929 | B4: 680000000
A5: 198.2878 | B5: 680000000
A6: 220.05629 | B6: 680000000
A7: 252.40789 | B7: 680000000
A8: 275.35094 | B8: 680000000
A9: 373.59142 | B9: 680000000
A10: 376.97767 | B10: 43000000
A11: 450.65924 | B11: 96000000
A12: 561.19762 | B12: 138000000
A13: 613.97919 | B13: 137000000
A14: 687.58137 | B14: 116000000
... A2692: 908.78232 | B2692: 749000000

Sheet gdpcapita and population urban
A1: GDP/CAPITA | B1: Population Urban
A2: 3 | B2: 0.213 | C2: correlation | D2: =CORREL(A2:A2692,B2:B2692) -> 0.45031947
A3: 115.31251 | B3: 0.216
A4: 185.95929 | B4: 0.219
A5: 198.2878 | B5: 0.222
A6: 220.05629 | B6: 0.226
A7: 252.40789 | B7: 0.229
A8: 275.35094 | B8: 0.232
A9: 373.59142 | B9: 0.236
A10: 376.97767 | B10: 0.239
A11: 450.65924 | B11: 0.243
A12: 561.19762 | B12: 0.247
A13: 613.97919 | B13: 0.251
A14: 687.58137 | B14: 0.255
... A2692: 908.78232 | B2692: 0.328

Sheet gdpcapita vs tourism outboundca
A1: GDP/CAPITA | B1: Tourism Outbound/Capita
A2: 3 | B2: 21.752472
A3: 115.31251 | B3: 20.985787 | C3: correlation | D3: =CORREL(A2:A2692,B2:B2692) -> 0.42906134
A4: 185.95929 | B4: 20.17763
A5: 198.2878 | B5: 19.380397
A6: 220.05629 | B6: 18.652148
A7: 252.40789 | B7: 18.020297
A8: 275.35094 | B8: 17.478642
A9: 373.59142 | B9: 17.002386
A10: 376.97767 | B10: 2.1455896
A11: 450.65924 | B11: 2.2015154
A12: 561.19762 | B12: 3.0284023
A13: 613.97919 | B13: 4.3634395
A14: 687.58137 | B14: 2.6823552
A15: 1193.4662 | B15: 93.880694
... A2692: 908.78232 | B2692: 32.64279

Sheet GDPCapita vs Energy UsageCapita
A1: GDP/CAPITA | B1: energy usage/capita | C1: co2 emissions per capita
A2: 3 | B2: 0.00069617623 | C2: 0.0004141224 | D2: correlation Energy/capita & GDP/Capita | E2: =CORREL(A2:A2692,B2:B2692) -> 0.24349877
A3: 115.31251 | B3: 0.00067163886 | C3: 0.00039952628 | D3: correlation CO2Emiission/capita & GDP/Capita | E3: =CORREL(A2:A2692,C2:C2692) -> 0.31090273
A4: 185.95929 | B4: 0.00064577423 | C4: 0.0003709441
A5: 198.2878 | B5: 0.00062025921 | C5: 0.00028222703
A6: 220.05629 | B6: 0.00059695199 | C6: 0.00016349773
A7: 252.40789 | B7: 0.00057672996 | C7: 8.0085741e-05
A8: 275.35094 | B8: 0.00055939457 | C8: 3.9639063e-05
A9: 373.59142 | B9: 0.00054415226 | C9: 2.2125873e-05
A10: 376.97767 | B10: 0.00053040454 | C10: 2.8891473e-05
A11: 450.65924 | B11: 0.00051746439 | C11: 4.8288977e-05
A12: 561.19762 | B12: 0.00050489805 | C12: 2.5811848e-05
A13: 613.97919 | B13: 0.00049262201 | C13: 2.2160775e-05
A14: 687.58137 | B14: 0.00048074512 | C14: 1.2037069e-05
A15: 1193.4662 | B15: 0.004641591 | C15: 0.0027610636
... A2692: 908.78232 | B2692: 0.00071879715 | C2692: 0.0010118536

Sheet HEALTH EXPCAPITA VS GDPCAPITA
A1: GDP/CAPITA | B1: Health Exp/Capita
A2: 3 | B2: 193
A3: 115.31251 | B3: 193 | C3: correlatiion | D3: =CORREL(A2:A2692,B2:B2692) -> 0.75625376
A4: 185.95929 | B4: 14
A5: 198.2878 | B5: 18
A6: 220.05629 | B6: 19
A7: 252.40789 | B7: 21
A8: 275.35094 | B8: 23
A9: 373.59142 | B9: 30
A10: 376.97767 | B10: 35
A11: 450.65924 | B11: 35
A12: 561.19762 | B12: 43
A13: 613.97919 | B13: 48
A14: 687.58137 | B14: 51
A15: 1193.4662 | B15: 70
... A2692: 908.78232 | B2692: 193

Sheet processed sheet
A1: ID | B1: Country/Region | C1: YEAR | D1: Region | E1: GDP | F1: GDP/CAPITA | G1: Health Exp % GDP | H1: Health Exp/Capita | I1: Lending Interest | J1: Energy Usage | K1: CO2 Emissions | L1: energy usage/capita | M1: co2 emissions per capita | N1: Birth Rate | O1: Infant Mortality Rate | P1: Life Expectancy Female | Q1: Life Expectancy Male | R1: Population 0-14 | S1: Population 15-64 | T1: Population 65+ | U1: Population Total | V1: Population Urban | W1: Tourism Inbound | X1: Tourism Outbound | Y1: Tourism Outbound/Capita | Z1: Business Tax Rate | AA1: Days to Start Business | AB1: Ease of Business | AC1: Hours to do Tax | AD1: Internet Usage | AE1: Mobile Phone Usage
A2: =CONCAT(B2,C2) -> Afghanistan-Asia2000 | B2: Afghanistan-Asia | C2: 2000 | D2: Asia | F2: 3 | G2: 0.064 | H2: 193 | I2: 0.148 | J2: {=VLOOKUP(A2,ENERGY!$A$2:$F$2692,{5,6},0)} -> 14338 | K2: 8529 | L2: =J2/'HUMAN RESOURCES'!I2 -> 0.00069617623 | M2: =K2/'HUMAN RESOURCES'!I2 -> 0.0004141224 | N2: {=VLOOKUP(A2,'HUMAN RESOURCES'!$A$2:$M$2692,{2,3,4,5,6,7,8,9,10},0)} -> 0.05 | O2: 0.095 | P2: 56 | Q2: 54 | R2: 0.495 | S2: 0.485 | T2: 0.02 | U2: 20595360 | V2: 0.213 | W2: {=VLOOKUP(A2,TOURISM!$A$2:$F$2692,{3,6},0)} -> 680000000 | X2: 448000000 | Y2: =X2/'HUMAN RESOURCES'!I2 -> 21.752472 | Z2: {=VLOOKUP(A2,BUSINESS!$A$2:$J$2692,{4,5,6,7,8,9},0)} -> 0.489 | AA2: 26 | AB2: 94 | AC2: 302 | AD2: 0.129 | AE2: 0.58
A3: =CONCAT(B3,C3) -> Afghanistan-Asia2001 | B3: Afghanistan-Asia | C3: 2001 | D3: Asia | E3: 2461666315 | F3: =E3/'HUMAN RESOURCES'!I3 -> 115.31251 | G3: 0.064 | H3: 193 | I3: 0.148 | J3: {=VLOOKUP(A3,ENERGY!$A$2:$F$2692,{5,6},0)} -> 14338 | K3: 8529 | L3: =J3/'HUMAN RESOURCES'!I3 -> 0.00067163886 | M3: =K3/'HUMAN RESOURCES'!I3 -> 0.00039952628 | N3: {=VLOOKUP(A3,'HUMAN RESOURCES'!$A$2:$M$2692,{2,3,4,5,6,7,8,9,10},0)} -> 0.049 | O3: 0.093 | P3: 56 | Q3: 54 | R3: 0.495 | S3: 0.484 | T3: 0.02 | U3: 21347782 | V3: 0.216 | W3: {=VLOOKUP(A3,TOURISM!$A$2:$F$2692,{3,6},0)} -> 680000000 | X3: 448000000 | Y3: =X3/'HUMAN RESOURCES'!I3 -> 20.985787 | Z3: {=VLOOKUP(A3,BUSINESS!$A$2:$J$2692,{4,5,6,7,8,9},0)} -> 0.489 | AA3: 26 | AB3: 94 | AC3: 302 | AD3: 0 | AE3: 0.58
A4: =CONCAT(B4,C4) -> Afghanistan-Asia2002 | B4: Afghanistan-Asia | C4: 2002 | D4: Asia | E4: 4128818043 | F4: =E4/'HUMAN RESOURCES'!I4 -> 185.95929 | G4: 0.089 | H4: 14 | I4: 0.148 | J4: {=VLOOKUP(A4,ENERGY!$A$2:$F$2692,{5,6},0)} -> 14338 | K4: 8236 | L4: =J4/'HUMAN RESOURCES'!I4 -> 0.00064577423 | M4: =K4/'HUMAN RESOURCES'!I4 -> 0.00037094411 | N4: {=VLOOKUP(A4,'HUMAN RESOURCES'!$A$2:$M$2692,{2,3,4,5,6,7,8,9,10},0)} -> 0.048 | O4: 0.091 | P4: 57 | Q4: 55 | R4: 0.495 | S4: 0.485 | T4: 0.02 | U4: 22202806 | V4: 0.219 | W4: {=VLOOKUP(A4,TOURISM!$A$2:$F$2692,{3,6},0)} -> 680000000 | X4: 448000000 | Y4: =X4/'HUMAN RESOURCES'!I4 -> 20.17763 | Z4: {=VLOOKUP(A4,BUSINESS!$A$2:$J$2692,{4,5,6,7,8,9},0)} -> 0.489 | AA4: 26 | AB4: 94 | AC4: 302 | AD4: 0 | AE4: 0.001
A5: =CONCAT(B5,C5) -> Afghanistan-Asia2003 | B5: Afghanistan-Asia | C5: 2003 | D5: Asia | E5: 4583648922 | F5: =E5/'HUMAN RESOURCES'!I5 -> 198.2878 | G5: 0.1 | H5: 18 | I5: 0.148 | J5: {=VLOOKUP(A5,ENERGY!$A$2:$F$2692,{5,6},0)} -> 14338 | K5: 6524 | L5: =J5/'HUMAN RESOURCES'!I5 -> 0.00062025921 | M5: =K5/'HUMAN RESOURCES'!I5 -> 0.00028222703 | N5: {=VLOOKUP(A5,'HUMAN RESOURCES'!$A$2:$M$2692,{2,3,4,5,6,7,8,9,10},0)} -> 0.047 | O5: 0.088 | P5: 57 | Q5: 55 | R5: 0.494 | S5: 0.485 | T5: 0.02 | U5: 23116142 | V5: 0.222 | W5: {=VLOOKUP(A5,TOURISM!$A$2:$F$2692,{3,6},0)} -> 680000000 | X5: 448000000 | Y5: =X5/'HUMAN RESOURCES'!I5 -> 19.380397 | Z5: {=VLOOKUP(A5,BUSINESS!$A$2:$J$2692,{4,5,6,7,8,9},0)} -> 0.489 | AA5: 26 | AB5: 94 | AC5: 302 | AD5: 0.001 | AE5: 0.009
A6: =CONCAT(B6,C6) -> Afghanistan-Asia2004 | B6: Afghanistan-Asia | C6: 2004 | D6: Asia | E6: 5285461999 | F6: =E6/'HUMAN RESOURCES'!I6 -> 220.05629 | G6: 0.098 | H6: 19 | I6: 0.148 | J6: {=VLOOKUP(A6,ENERGY!$A$2:$F$2692,{5,6},0)} -> 14338 | K6: 3927 | L6: =J6/'HUMAN RESOURCES'!I6 -> 0.00059695199 | M6: =K6/'HUMAN RESOURCES'!I6 -> 0.00016349773 | N6: {=VLOOKUP(A6,'HUMAN RESOURCES'!$A$2:$M$2692,{2,3,4,5,6,7,8,9,10},0)} -> 0.046 | O6: 0.086 | P6: 58 | Q6: 55 | R6: 0.494 | S6: 0.486 | T6: 0.02 | U6: 24018682 | V6: 0.226 | W6: {=VLOOKUP(A6,TOURISM!$A$2:$F$2692,{3,6},0)} -> 680000000 | X6: 448000000 | Y6: =X6/'HUMAN RESOURCES'!I6 -> 18.652148 | Z6: {=VLOOKUP(A6,BUSINESS!$A$2:$J$2692,{4,5,6,7,8,9},0)} -> 0.489 | AA6: 9 | AB6: 94 | AC6: 302 | AD6: 0.001 | AE6: 0.025
A7: =CONCAT(B7,C7) -> Afghanistan-Asia2005 | B7: Afghanistan-Asia | C7: 2005 | D7: Asia | E7: 6275076016 | F7: =E7/'HUMAN RESOURCES'!I7 -> 252.40789 | G7: 0.092 | H7: 21 | I7: 0.148 | J7: {=VLOOKUP(A7,ENERGY!$A$2:$F$2692,{5,6},0)} -> 14338 | K7: 1991 | L7: =J7/'HUMAN RESOURCES'!I7 -> 0.00057672996 | M7: =K7/'HUMAN RESOURCES'!I7 -> 8.0085741e-05 | N7: {=VLOOKUP(A7,'HUMAN RESOURCES'!$A$2:$M$2692,{2,3,4,5,6,7,8,9,10},0)} -> 0.045 | O7: 0.084 | P7: 58 | Q7: 56 | R7: 0.493 | S7: 0.487 | T7: 0.02 | U7: 24860855 | V7: 0.229 | W7: {=VLOOKUP(A7,TOURISM!$A$2:$F$2692,{3,6},0)} -> 680000000 | X7: 448000000 | Y7: =X7/'HUMAN RESOURCES'!I7 -> 18.020297 | Z7: {=VLOOKUP(A7,BUSINESS!$A$2:$J$2692,{4,5,6,7,8,9},0)} -> 0.363 | AA7: 9 | AB7: 94 | AC7: 275 | AD7: 0.012 | AE7: 0.048
A8: =CONCAT(B8,C8) -> Afghanistan-Asia2006 | B8: Afghanistan-Asia | C8: 2006 | D8: Asia | E8: 7057597615 | F8: =E8/'HUMAN RESOURCES'!I8 -> 275.35094 | G8: 0.091 | H8: 23 | I8: 0.18 | J8: {=VLOOKUP(A8,ENERGY!$A$2:$F$2692,{5,6},0)} -> 14338 | K8: 1016 | L8: =J8/'HUMAN RESOURCES'!I8 -> 0.00055939457 | M8: =K8/'HUMAN RESOURCES'!I8 -> 3.9639063e-05 | N8: {=VLOOKUP(A8,'HUMAN RESOURCES'!$A$2:$M$2692,{2,3,4,5,6,7,8,9,10},0)} -> 0.044 | O8: 0.082 | P8: 59 | Q8: 56 | R8: 0.493 | S8: 0.487 | T8: 0.02 | U8: 25631282 | V8: 0.232 | W8: {=VLOOKUP(A8,TOURISM!$A$2:$F$2692,{3,6},0)} -> 680000000 | X8: 448000000 | Y8: =X8/'HUMAN RESOURCES'!I8 -> 17.478642 | Z8: {=VLOOKUP(A8,BUSINESS!$A$2:$J$2692,{4,5,6,7,8,9},0)} -> 0.363 | AA8: 9 | AB8: 94 | AC8: 275 | AD8: 0.021 | AE8: 0.098
A9: =CONCAT(B9,C9) -> Afghanistan-Asia2007 | B9: Afghanistan-Asia | C9: 2007 | D9: Asia | E9: 9843851009 | F9: =E9/'HUMAN RESOURCES'!I9 -> 373.59142 | G9: 0.1 | H9: 30 | I9: 0.181 | J9: {=VLOOKUP(A9,ENERGY!$A$2:$F$2692,{5,6},0)} -> 14338 | K9: 583 | L9: =J9/'HUMAN RESOURCES'!I9 -> 0.00054415226 | M9: =K9/'HUMAN RESOURCES'!I9 -> 2.2125873e-05 | N9: {=VLOOKUP(A9,'HUMAN RESOURCES'!$A$2:$M$2692,{2,3,4,5,6,7,8,9,10},0)} -> 0.042 | O9: 0.08 | P9: 59 | Q9: 57 | R9: 0.492 | S9: 0.487 | T9: 0.021 | U9: 26349243 | V9: 0.236 | W9: {=VLOOKUP(A9,TOURISM!$A$2:$F$2692,{3,6},0)} -> 680000000 | X9: 448000000 | Y9: =X9/'HUMAN RESOURCES'!I9 -> 17.002386 | Z9: {=VLOOKUP(A9,BUSINESS!$A$2:$J$2692,{4,5,6,7,8,9},0)} -> 0.363 | AA9: 9 | AB9: 94 | AC9: 275 | AD9: 0.019 | AE9: 0.177
A10: =CONCAT(B10,C10) -> Afghanistan-Asia2008 | B10: Afghanistan-Asia | C10: 2008 | D10: Asia | E10: 10190534636 | F10: =E10/'HUMAN RESOURCES'!I10 -> 376.97767 | G10: 0.097 | H10: 35 | I10: 0.149 | J10: {=VLOOKUP(A10,ENERGY!$A$2:$F$2692,{5,6},0)} -> 14338 | K10: 781 | L10: =J10/'HUMAN RESOURCES'!I10 -> 0.00053040454 | M10: =K10/'HUMAN RESOURCES'!I10 -> 2.8891473e-05 | N10: {=VLOOKUP(A10,'HUMAN RESOURCES'!$A$2:$M$2692,{2,3,4,5,6,7,8,9,10},0)} -> 0.041 | O10: 0.079 | P10: 60 | Q10: 57 | R10: 0.492 | S10: 0.487 | T10: 0.021 | U10: 27032197 | V10: 0.239 | W10: {=VLOOKUP(A10,TOURISM!$A$2:$F$2692,{3,6},0)} -> 43000000 | X10: 58000000 | Y10: =X10/'HUMAN RESOURCES'!I10 -> 2.1455896 | Z10: {=VLOOKUP(A10,BUSINESS!$A$2:$J$2692,{4,5,6,7,8,9},0)} -> 0.363 | AA10: 9 | AB10: 94 | AC10: 275 | AD10: 0.018 | AE10: 0.292
A11: =CONCAT(B11,C11) -> Afghanistan-Asia2009 | B11: Afghanistan-Asia | C11: 2009 | D11: Asia | E11: 12486950469 | F11: =E11/'HUMAN RESOURCES'!I11 -> 450.65924 | G11: 0.087 | H11: 35 | I11: 0.15 | J11: {=VLOOKUP(A11,ENERGY!$A$2:$F$2692,{5,6},0)} -> 14338 | K11: 1338 | L11: =J11/'HUMAN RESOURCES'!I11 -> 0.00051746439 | M11: =K11/'HUMAN RESOURCES'!I11 -> 4.8288977e-05 | N11: {=VLOOKUP(A11,'HUMAN RESOURCES'!$A$2:$M$2692,{2,3,4,5,6,7,8,9,10},0)} -> 0.039 | O11: 0.077 | P11: 60 | Q11: 58 | R11: 0.49 | S11: 0.489 | T11: 0.021 | U11: 27708187 | V11: 0.243 | W11: {=VLOOKUP(A11,TOURISM!$A$2:$F$2692,{3,6},0)} -> 96000000 | X11: 61000000 | Y11: =X11/'HUMAN RESOURCES'!I11 -> 2.2015154 | Z11: {=VLOOKUP(A11,BUSINESS!$A$2:$J$2692,{4,5,6,7,8,9},0)} -> 0.363 | AA11: 7 | AB11: 94 | AC11: 275 | AD11: 0.036 | AE11: 0.379
A12: =CONCAT(B12,C12) -> Afghanistan-Asia2010 | B12: Afghanistan-Asia | C12: 2010 | D12: Asia | E12: 15936784436 | F12: =E12/'HUMAN RESOURCES'!I12 -> 561.19762 | G12: 0.087 | H12: 43 | I12: 0.157 | J12: {=VLOOKUP(A12,ENERGY!$A$2:$F$2692,{5,6},0)} -> 14338 | K12: 733 | L12: =J12/'HUMAN RESOURCES'!I12 -> 0.00050489805 | M12: =K12/'HUMAN RESOURCES'!I12 -> 2.5811848e-05 | N12: {=VLOOKUP(A12,'HUMAN RESOURCES'!$A$2:$M$2692,{2,3,4,5,6,7,8,9,10},0)} -> 0.038 | O12: 0.075 | P12: 61 | Q12: 58 | R12: 0.486 | S12: 0.492 | T12: 0.022 | U12: 28397812 | V12: 0.247 | W12: {=VLOOKUP(A12,TOURISM!$A$2:$F$2692,{3,6},0)} -> 138000000 | X12: 86000000 | Y12: =X12/'HUMAN RESOURCES'!I12 -> 3.0284023 | Z12: {=VLOOKUP(A12,BUSINESS!$A$2:$J$2692,{4,5,6,7,8,9},0)} -> 0.363 | AA12: 7 | AB12: 94 | AC12: 275 | AD12: 0.04 | AE12: 0.458
A13: =CONCAT(B13,C13) -> Afghanistan-Asia2011 | B13: Afghanistan-Asia | C13: 2011 | D13: Asia | E13: 17870159082 | F13: =E13/'HUMAN RESOURCES'!I13 -> 613.97919 | G13: 0.084 | H13: 48 | I13: 0.151 | J13: {=VLOOKUP(A13,ENERGY!$A$2:$F$2692,{5,6},0)} -> 14338 | K13: 645 | L13: =J13/'HUMAN RESOURCES'!I13 -> 0.00049262201 | M13: =K13/'HUMAN RESOURCES'!I13 -> 2.2160775e-05 | N13: {=VLOOKUP(A13,'HUMAN RESOURCES'!$A$2:$M$2692,{2,3,4,5,6,7,8,9,10},0)} -> 0.037 | O13: 0.074 | P13: 61 | Q13: 59 | R13: 0.481 | S13: 0.497 | T13: 0.022 | U13: 29105480 | V13: 0.251 | W13: {=VLOOKUP(A13,TOURISM!$A$2:$F$2692,{3,6},0)} -> 137000000 | X13: 127000000 | Y13: =X13/'HUMAN RESOURCES'!I13 -> 4.3634395 | Z13: {=VLOOKUP(A13,BUSINESS!$A$2:$J$2692,{4,5,6,7,8,9},0)} -> 0.363 | AA13: 7 | AB13: 94 | AC13: 275 | AD13: 0.05 | AE13: 0.603
A14: =CONCAT(B14,C14) -> Afghanistan-Asia2012 | B14: Afghanistan-Asia | C14: 2012 | D14: Asia | E14: 20506795254 | F14: =E14/'HUMAN RESOURCES'!I14 -> 687.58137 | G14: 0.086 | H14: 51 | I14: 0.15 | J14: {=VLOOKUP(A14,ENERGY!$A$2:$F$2692,{5,6},0)} -> 14338 | K14: 359 | L14: =J14/'HUMAN RESOURCES'!I14 -> 0.00048074512 | M14: =K14/'HUMAN RESOURCES'!I14 -> 1.2037069e-05 | N14: {=VLOOKUP(A14,'HUMAN RESOURCES'!$A$2:$M$2692,{2,3,4,5,6,7,8,9,10},0)} -> 0.035 | O14: 0.072 | P14: 62 | Q14: 59 | R14: 0.474 | S14: 0.503 | T14: 0.023 | U14: 29824536 | V14: 0.255 | W14: {=VLOOKUP(A14,TOURISM!$A$2:$F$2692,{3,6},0)} -> 116000000 | X14: 80000000 | Y14: =X14/'HUMAN RESOURCES'!I14 -> 2.6823552 | Z14: {=VLOOKUP(A14,BUSINESS!$A$2:$J$2692,{4,5,6,7,8,9},0)} -> 0.363 | AA14: 7 | AB14: 170 | AC14: 275 | AD14: 0.055 | AE14: 0.655
... A40: =CONCAT(B40,C40) -> Algeria-Africa2012 | B40: Algeria-Africa | C40: 2012 | D40: Africa | E40: 204000000000 | F40: =E40/'HUMAN RESOURCES'!I40 -> 5301.2204 | G40: 0.052 | H40: 279 | I40: 0.08 | J40: {=VLOOKUP(A40,ENERGY!$A$2:$F$2692,{5,6},0)} -> 28773 | K40: 90854 | L40: =J40/'HUMAN RESOURCES'!I40 -> 0.00074770596 | M40: =K40/'HUMAN RESOURCES'!I40 -> 0.0023609661 | N40: {=VLOOKUP(A40,'HUMAN RESOURCES'!$A$2:$M$2692,{2,3,4,5,6,7,8,9,10},0)} -> 0.025 | O40: 0.022 | P40: 73 | Q40: 69 | R40: 0.274 | S40: 0.679 | T40: 0.047 | U40: 38481705 | V40: 0.689 | W40: {=VLOOKUP(A40,TOURISM!$A$2:$F$2692,{3,6},0)} -> 295000000 | X40: 559000000 | Y40: =X40/'HUMAN RESOURCES'!I40 -> 14.526383 | Z40: {=VLOOKUP(A40,BUSINESS!$A$2:$J$2692,{4,5,6,7,8,9},0)} -> 0.719 | AA40: 25 | AB40: 151 | AC40: 451 | AD40: 0.152 | AE40: 0.975
A41: =CONCAT(B41,C41) -> American Samoa-Oceania2000 | B41: American Samoa-Oceania | C41: 2000 | D41: Oceania | F41: =E41/'HUMAN RESOURCES'!I41 -> 0 | G41: 0.064 | H41: 193 | I41: 0.148 | J41: {=VLOOKUP(A41,ENERGY!$A$2:$F$2692,{5,6},0)} -> 14338 | K41: 8529 | L41: =J41/'HUMAN RESOURCES'!I41 -> 0.24926115 | M41: =K41/'HUMAN RESOURCES'!I41 -> 0.1482737 | N41: {=VLOOKUP(A41,'HUMAN RESOURCES'!$A$2:$M$2692,{2,3,4,5,6,7,8,9,10},0)} -> 0.022763997 | O41: 0.032 | P41: 71 | Q41: 66 | R41: 0.0303 | S41: 0.623 | T41: 0.073 | U41: 57522 | V41: 0.886 | W41: {=VLOOKUP(A41,TOURISM!$A$2:$F$2692,{3,6},0)} -> 680000000 | X41: 448000000 | Y41: =X41/'HUMAN RESOURCES'!I41 -> 7788.3245 | Z41: {=VLOOKUP(A41,BUSINESS!$A$2:$J$2692,{4,5,6,7,8,9},0)} -> 0.489 | AA41: 26 | AB41: 94 | AC41: 302 | AD41: 0.129 | AE41: 0.035
A42: =CONCAT(B42,C42) -> American Samoa-Oceania2001 | B42: American Samoa-Oceania | C42: 2001 | D42: Oceania | F42: =E42/'HUMAN RESOURCES'!I42 -> 0 | G42: 0.064 | H42: 193 | I42: 0.148 | J42: {=VLOOKUP(A42,ENERGY!$A$2:$F$2692,{5,6},0)} -> 14338 | K42: 8529 | L42: =J42/'HUMAN RESOURCES'!I42 -> 0.24645902 | M42: =K42/'HUMAN RESOURCES'!I42 -> 0.14660685 | N42: {=VLOOKUP(A42,'HUMAN RESOURCES'!$A$2:$M$2692,{2,3,4,5,6,7,8,9,10},0)} -> 0.022763997 | O42: 0.032 | P42: 71 | Q42: 66 | R42: 0.0303 | S42: 0.623 | T42: 0.073 | U42: 58176 | V42: 0.885 | W42: {=VLOOKUP(A42,TOURISM!$A$2:$F$2692,{3,6},0)} -> 680000000 | X42: 448000000 | Y42: =X42/'HUMAN RESOURCES'!I42 -> 7700.7701 | Z42: {=VLOOKUP(A42,BUSINESS!$A$2:$J$2692,{4,5,6,7,8,9},0)} -> 0.489 | AA42: 26 | AB42: 94 | AC42: 302 | AD42: 0.129 | AE42: 0.037
A43: =CONCAT(B43,C43) -> American Samoa-Oceania2002 | B43: American Samoa-Oceania | C43: 2002 | D43: Oceania | F43: =E43/'HUMAN RESOURCES'!I43 -> 0 | G43: 0.064 | H43: 193 | I43: 0.148 | J43: {=VLOOKUP(A43,ENERGY!$A$2:$F$2692,{5,6},0)} -> 14338 | K43: 8529 | L43: =J43/'HUMAN RESOURCES'!I43 -> 0.24413833 | M43: =K43/'HUMAN RESOURCES'!I43 -> 0.14522638 | N43: {=VLOOKUP(A43,'HUMAN RESOURCES'!$A$2:$M$2692,{2,3,4,5,6,7,8,9,10},0)} -> 0.022763997 | O43: 0.032 | P43: 71 | Q43: 66 | R43: 0.0303 | S43: 0.623 | T43: 0.073 | U43: 58729 | V43: 0.884 | W43: {=VLOOKUP(A43,TOURISM!$A$2:$F$2692,{3,6},0)} -> 680000000 | X43: 448000000 | Y43: =X43/'HUMAN RESOURCES'!I43 -> 7628.2586 | Z43: {=VLOOKUP(A43,BUSINESS!$A$2:$J$2692,{4,5,6,7,8,9},0)} -> 0.489 | AA43: 26 | AB43: 94 | AC43: 302 | AD43: 0.129 | AE43: 0.035
A44: =CONCAT(B44,C44) -> American Samoa-Oceania2003 | B44: American Samoa-Oceania | C44: 2003 | D44: Oceania | F44: =E44/'HUMAN RESOURCES'!I44 -> 0 | G44: 0.064 | H44: 193 | I44: 0.148 | J44: {=VLOOKUP(A44,ENERGY!$A$2:$F$2692,{5,6},0)} -> 14338 | K44: 8529 | L44: =J44/'HUMAN RESOURCES'!I44 -> 0.24253599 | M44: =K44/'HUMAN RESOURCES'!I44 -> 0.14427322 | N44: {=VLOOKUP(A44,'HUMAN RESOURCES'!$A$2:$M$2692,{2,3,4,5,6,7,8,9,10},0)} -> 0.022763997 | O44: 0.032 | P44: 71 | Q44: 66 | R44: 0.0303 | S44: 0.623 | T44: 0.073 | U44: 59117 | V44: 0.883 | W44: {=VLOOKUP(A44,TOURISM!$A$2:$F$2692,{3,6},0)} -> 680000000 | X44: 448000000 | Y44: =X44/'HUMAN RESOURCES'!I44 -> 7578.1924 | Z44: {=VLOOKUP(A44,BUSINESS!$A$2:$J$2692,{4,5,6,7,8,9},0)} -> 0.489 | AA44: 26 | AB44: 94 | AC44: 302 | AD44: 0.129 | AE44: 0.036
A45: =CONCAT(B45,C45) -> American Samoa-Oceania2004 | B45: American Samoa-Oceania | C45: 2004 | D45: Oceania | F45: =E45/'HUMAN RESOURCES'!I45 -> 0 | G45: 0.064 | H45: 193 | I45: 0.148 | J45: {=VLOOKUP(A45,ENERGY!$A$2:$F$2692,{5,6},0)} -> 14338 | K45: 8529 | L45: =J45/'HUMAN RESOURCES'!I45 -> 0.24194256 | M45: =K45/'HUMAN RESOURCES'!I45 -> 0.14392022 | N45: {=VLOOKUP(A45,'HUMAN RESOURCES'!$A$2:$M$2692,{2,3,4,5,6,7,8,9,10},0)} -> 0.022763997 | O45: 0.032 | P45: 71 | Q45: 66 | R45: 0.0303 | S45: 0.623 | T45: 0.073 | U45: 59262 | V45: 0.882 | W45: {=VLOOKUP(A45,TOURISM!$A$2:$F$2692,{3,6},0)} -> 680000000 | X45: 448000000 | Y45: =X45/'HUMAN RESOURCES'!I45 -> 7559.6504 | Z45: {=VLOOKUP(A45,BUSINESS!$A$2:$J$2692,{4,5,6,7,8,9},0)} -> 0.489 | AA45: 26 | AB45: 94 | AC45: 302 | AD45: 0.129 | AE45: 0.038
A46: =CONCAT(B46,C46) -> American Samoa-Oceania2005 | B46: American Samoa-Oceania | C46: 2005 | D46: Oceania | F46: =E46/'HUMAN RESOURCES'!I46 -> 0 | G46: 0.064 | H46: 193 | I46: 0.148 | J46: {=VLOOKUP(A46,ENERGY!$A$2:$F$2692,{5,6},0)} -> 14338 | K46: 8529 | L46: =J46/'HUMAN RESOURCES'!I46 -> 0.24253599 | M46: =K46/'HUMAN RESOURCES'!I46 -> 0.14427322 | N46: {=VLOOKUP(A46,'HUMAN RESOURCES'!$A$2:$M$2692,{2,3,4,5,6,7,8,9,10},0)} -> 0.022763997 | O46: 0.032 | P46: 71 | Q46: 66 | R46: 0.0303 | S46: 0.623 | T46: 0.073 | U46: 59117 | V46: 0.881 | W46: {=VLOOKUP(A46,TOURISM!$A$2:$F$2692,{3,6},0)} -> 680000000 | X46: 448000000 | Y46: =X46/'HUMAN RESOURCES'!I46 -> 7578.1924 | Z46: {=VLOOKUP(A46,BUSINESS!$A$2:$J$2692,{4,5,6,7,8,9},0)} -> 0.489 | AA46: 26 | AB46: 94 | AC46: 302 | AD46: 0.129 | AE46: 0.58
A47: =CONCAT(B47,C47) -> American Samoa-Oceania2006 | B47: American Samoa-Oceania | C47: 2006 | D47: Oceania | F47: =E47/'HUMAN RESOURCES'!I47 -> 0 | G47: 0.064 | H47: 193 | I47: 0.148 | J47: {=VLOOKUP(A47,ENERGY!$A$2:$F$2692,{5,6},0)} -> 14338 | K47: 8529 | L47: =J47/'HUMAN RESOURCES'!I47 -> 0.24445884 | M47: =K47/'HUMAN RESOURCES'!I47 -> 0.14541704 | N47: {=VLOOKUP(A47,'HUMAN RESOURCES'!$A$2:$M$2692,{2,3,4,5,6,7,8,9,10},0)} -> 0.022 | O47: 0.032 | P47: 71 | Q47: 66 | R47: 0.0303 | S47: 0.623 | T47: 0.073 | U47: 58652 | V47: 0.88 | W47: {=VLOOKUP(A47,TOURISM!$A$2:$F$2692,{3,6},0)} -> 680000000 | X47: 448000000 | Y47: =X47/'HUMAN RESOURCES'!I47 -> 7638.2732 | Z47: {=VLOOKUP(A47,BUSINESS!$A$2:$J$2692,{4,5,6,7,8,9},0)} -> 0.489 | AA47: 26 | AB47: 94 | AC47: 302 | AD47: 0.129 | AE47: 0.58
A48: =CONCAT(B48,C48) -> American Samoa-Oceania2007 | B48: American Samoa-Oceania | C48: 2007 | D48: Oceania | F48: =E48/'HUMAN RESOURCES'!I48 -> 0 | G48: 0.064 | H48: 193 | I48: 0.148 | J48: {=VLOOKUP(A48,ENERGY!$A$2:$F$2692,{5,6},0)} -> 14338 | K48: 8529 | L48: =J48/'HUMAN RESOURCES'!I48 -> 0.24755262 | M48: =K48/'HUMAN RESOURCES'!I48 -> 0.14725738 | N48: {=VLOOKUP(A48,'HUMAN RESOURCES'!$A$2:$M$2692,{2,3,4,5,6,7,8,9,10},0)} -> 0.022763997 | O48: 0.032 | P48: 71 | Q48: 66 | R48: 0.0303 | S48: 0.623 | T48: 0.073 | U48: 57919 | V48: 0.879 | W48: {=VLOOKUP(A48,TOURISM!$A$2:$F$2692,{3,6},0)} -> 680000000 | X48: 448000000 | Y48: =X48/'HUMAN RESOURCES'!I48 -> 7734.9402 | Z48: {=VLOOKUP(A48,BUSINESS!$A$2:$J$2692,{4,5,6,7,8,9},0)} -> 0.489 | AA48: 26 | AB48: 94 | AC48: 302 | AD48: 0.129 | AE48: 0.58
A49: =CONCAT(B49,C49) -> American Samoa-Oceania2008 | B49: American Samoa-Oceania | C49: 2008 | D49: Oceania | F49: =E49/'HUMAN RESOURCES'!I49 -> 0 | G49: 0.064 | H49: 193 | I49: 0.148 | J49: {=VLOOKUP(A49,ENERGY!$A$2:$F$2692,{5,6},0)} -> 14338 | K49: 8529 | L49: =J49/'HUMAN RESOURCES'!I49 -> 0.25131019 | M49: =K49/'HUMAN RESOURCES'!I49 -> 0.14949258 | N49: {=VLOOKUP(A49,'HUMAN RESOURCES'!$A$2:$M$2692,{2,3,4,5,6,7,8,9,10},0)} -> 0.022763997 | O49: 0.032 | P49: 71 | Q49: 66 | R49: 0.0303 | S49: 0.623 | T49: 0.073 | U49: 57053 | V49: 0.878 | W49: {=VLOOKUP(A49,TOURISM!$A$2:$F$2692,{3,6},0)} -> 680000000 | X49: 448000000 | Y49: =X49/'HUMAN RESOURCES'!I49 -> 7852.3478 | Z49: {=VLOOKUP(A49,BUSINESS!$A$2:$J$2692,{4,5,6,7,8,9},0)} -> 0.489 | AA49: 26 | AB49: 94 | AC49: 302 | AD49: 0.129 | AE49: 0.58
A50: =CONCAT(B50,C50) -> American Samoa-Oceania2009 | B50: American Samoa-Oceania | C50: 2009 | D50: Oceania | F50: =E50/'HUMAN RESOURCES'!I50 -> 0 | G50: 0.064 | H50: 193 | I50: 0.148 | J50: {=VLOOKUP(A50,ENERGY!$A$2:$F$2692,{5,6},0)} -> 14338 | K50: 8529 | L50: =J50/'HUMAN RESOURCES'!I50 -> 0.25492044 | M50: =K50/'HUMAN RESOURCES'!I50 -> 0.15164015 | N50: {=VLOOKUP(A50,'HUMAN RESOURCES'!$A$2:$M$2692,{2,3,4,5,6,7,8,9,10},0)} -> 0.022763997 | O50: 0.032 | P50: 71 | Q50: 66 | R50: 0.0303 | S50: 0.623 | T50: 0.073 | U50: 56245 | V50: 0.877 | W50: {=VLOOKUP(A50,TOURISM!$A$2:$F$2692,{3,6},0)} -> 680000000 | X50: 448000000 | Y50: =X50/'HUMAN RESOURCES'!I50 -> 7965.1525 | Z50: {=VLOOKUP(A50,BUSINESS!$A$2:$J$2692,{4,5,6,7,8,9},0)} -> 0.489 | AA50: 26 | AB50: 94 | AC50: 302 | AD50: 0.129 | AE50: 0.58
A51: =CONCAT(B51,C51) -> American Samoa-Oceania2010 | B51: American Samoa-Oceania | C51: 2010 | D51: Oceania | F51: =E51/'HUMAN RESOURCES'!I51 -> 0 | G51: 0.064 | H51: 193 | I51: 0.148 | J51: {=VLOOKUP(A51,ENERGY!$A$2:$F$2692,{5,6},0)} -> 14338 | K51: 8529 | L51: =J51/'HUMAN RESOURCES'!I51 -> 0.25771083 | M51: =K51/'HUMAN RESOURCES'!I51 -> 0.15330002 | N51: {=VLOOKUP(A51,'HUMAN RESOURCES'!$A$2:$M$2692,{2,3,4,5,6,7,8,9,10},0)} -> 0.019 | O51: 0.032 | P51: 71 | Q51: 66 | R51: 0.0303 | S51: 0.623 | T51: 0.073 | U51: 55636 | V51: 0.876 | W51: {=VLOOKUP(A51,TOURISM!$A$2:$F$2692,{3,6},0)} -> 680000000 | X51: 448000000 | Y51: =X51/'HUMAN RESOURCES'!I51 -> 8052.3402 | Z51: {=VLOOKUP(A51,BUSINESS!$A$2:$J$2692,{4,5,6,7,8,9},0)} -> 0.489 | AA51: 26 | AB51: 94 | AC51: 302 | AD51: 0.129 | AE51: 0.58
A52: =CONCAT(B52,C52) -> American Samoa-Oceania2011 | B52: American Samoa-Oceania | C52: 2011 | D52: Oceania | F52: =E52/'HUMAN RESOURCES'!I52 -> 0 | G52: 0.064 | H52: 193 | I52: 0.148 | J52: {=VLOOKUP(A52,ENERGY!$A$2:$F$2692,{5,6},0)} -> 14338 | K52: 8529 | L52: =J52/'HUMAN RESOURCES'!I52 -> 0.25939863 | M52: =K52/'HUMAN RESOURCES'!I52 -> 0.15430401 | N52: {=VLOOKUP(A52,'HUMAN RESOURCES'!$A$2:$M$2692,{2,3,4,5,6,7,8,9,10},0)} -> 0.022763997 | O52: 0.032 | P52: 71 | Q52: 66 | R52: 0.0303 | S52: 0.623 | T52: 0.073 | U52: 55274 | V52: 0.875 | W52: {=VLOOKUP(A52,TOURISM!$A$2:$F$2692,{3,6},0)} -> 680000000 | X52: 448000000 | Y52: =X52/'HUMAN RESOURCES'!I52 -> 8105.0765 | Z52: {=VLOOKUP(A52,BUSINESS!$A$2:$J$2692,{4,5,6,7,8,9},0)} -> 0.489 | AA52: 26 | AB52: 94 | AC52: 302 | AD52: 0.129 | AE52: 0.58
... A54: =CONCAT(B54,C54) -> Andorra-Europe2000 | B54: Andorra-Europe | C54: 2000 | D54: Europe | F54: =E54/'HUMAN RESOURCES'!I54 -> 0 | G54: 0.083 | H54: 3057 | I54: 0.148 | J54: {=VLOOKUP(A54,ENERGY!$A$2:$F$2692,{5,6},0)} -> 14338 | K54: 8529 | L54: =J54/'HUMAN RESOURCES'!I54 -> 0.21923883 | M54: =K54/'HUMAN RESOURCES'!I54 -> 0.13041484 | N54: {=VLOOKUP(A54,'HUMAN RESOURCES'!$A$2:$M$2692,{2,3,4,5,6,7,8,9,10},0)} -> 0.011 | O54: 0.004 | P54: 71 | Q54: 66 | R54: 0.0303 | S54: 0.623 | T54: 0.073 | U54: 65399 | V54: 0.924 | W54: {=VLOOKUP(A54,TOURISM!$A$2:$F$2692,{3,6},0)} -> 680000000 | X54: 448000000 | Y54: =X54/'HUMAN RESOURCES'!I54 -> 6850.2576 | Z54: {=VLOOKUP(A54,BUSINESS!$A$2:$J$2692,{4,5,6,7,8,9},0)} -> 0.489 | AA54: 26 | AB54: 94 | AC54: 302 | AD54: 0.105 | AE54: 0.36
A55: =CONCAT(B55,C55) -> Andorra-Europe2001 | B55: Andorra-Europe | C55: 2001 | D55: Europe | E55: 1133644295 | F55: =E55/'HUMAN RESOURCES'!I55 -> 16671.24 | G55: 0.062 | H55: 1330 | I55: 0.148 | J55: {=VLOOKUP(A55,ENERGY!$A$2:$F$2692,{5,6},0)} -> 14338 | K55: 8529 | L55: =J55/'HUMAN RESOURCES'!I55 -> 0.21085294 | M55: =K55/'HUMAN RESOURCES'!I55 -> 0.12542647 | N55: {=VLOOKUP(A55,'HUMAN RESOURCES'!$A$2:$M$2692,{2,3,4,5,6,7,8,9,10},0)} -> 0.012 | O55: 0.004 | P55: 71 | Q55: 66 | R55: 0.0303 | S55: 0.623 | T55: 0.073 | U55: 68000 | V55: 0.921 | W55: {=VLOOKUP(A55,TOURISM!$A$2:$F$2692,{3,6},0)} -> 680000000 | X55: 448000000 | Y55: =X55/'HUMAN RESOURCES'!I55 -> 6588.2353 | Z55: {=VLOOKUP(A55,BUSINESS!$A$2:$J$2692,{4,5,6,7,8,9},0)} -> 0.489 | AA55: 26 | AB55: 94 | AC55: 302 | AD55: 0.129 | AE55: 0.433
A56: =CONCAT(B56,C56) -> Andorra-Europe2002 | B56: Andorra-Europe | C56: 2002 | D56: Europe | E56: 1264760246 | F56: =E56/'HUMAN RESOURCES'!I56 -> 17654.633 | G56: 0.056 | H56: 1294 | I56: 0.148 | J56: {=VLOOKUP(A56,ENERGY!$A$2:$F$2692,{5,6},0)} -> 14338 | K56: 517 | L56: =J56/'HUMAN RESOURCES'!I56 -> 0.20014238 | M56: =K56/'HUMAN RESOURCES'!I56 -> 0.0072167395 | N56: {=VLOOKUP(A56,'HUMAN RESOURCES'!$A$2:$M$2692,{2,3,4,5,6,7,8,9,10},0)} -> 0.011 | O56: 0.004 | P56: 71 | Q56: 66 | R56: 0.0303 | S56: 0.623 | T56: 0.073 | U56: 71639 | V56: 0.916 | W56: {=VLOOKUP(A56,TOURISM!$A$2:$F$2692,{3,6},0)} -> 680000000 | X56: 448000000 | Y56: =X56/'HUMAN RESOURCES'!I56 -> 6253.577 | Z56: {=VLOOKUP(A56,BUSINESS!$A$2:$J$2692,{4,5,6,7,8,9},0)} -> 0.489 | AA56: 26 | AB56: 94 | AC56: 302 | AD56: 0.113 | AE56: 0.458
A57: =CONCAT(B57,C57) -> Andorra-Europe2003 | B57: Andorra-Europe | C57: 2003 | D57: Europe | E57: 1456198796 | F57: =E57/'HUMAN RESOURCES'!I57 -> 19250.939 | G57: 0.058 | H57: 1486 | I57: 0.148 | J57: {=VLOOKUP(A57,ENERGY!$A$2:$F$2692,{5,6},0)} -> 14338 | K57: 517 | L57: =J57/'HUMAN RESOURCES'!I57 -> 0.18954827 | M57: =K57/'HUMAN RESOURCES'!I57 -> 0.0068347369 | N57: {=VLOOKUP(A57,'HUMAN RESOURCES'!$A$2:$M$2692,{2,3,4,5,6,7,8,9,10},0)} -> 0.01 | O57: 0.003 | P57: 71 | Q57: 66 | R57: 0.0303 | S57: 0.623 | T57: 0.073 | U57: 75643 | V57: 0.912 | W57: {=VLOOKUP(A57,TOURISM!$A$2:$F$2692,{3,6},0)} -> 680000000 | X57: 448000000 | Y57: =X57/'HUMAN RESOURCES'!I57 -> 5922.5573 | Z57: {=VLOOKUP(A57,BUSINESS!$A$2:$J$2692,{4,5,6,7,8,9},0)} -> 0.489 | AA57: 26 | AB57: 94 | AC57: 302 | AD57: 0.135 | AE57: 0.686
A58: =CONCAT(B58,C58) -> Andorra-Europe2004 | B58: Andorra-Europe | C58: 2004 | D58: Europe | E58: 1917948475 | F58: =E58/'HUMAN RESOURCES'!I58 -> 24259.404 | G58: 0.058 | H58: 1891 | I58: 0.148 | J58: {=VLOOKUP(A58,ENERGY!$A$2:$F$2692,{5,6},0)} -> 14338 | K58: 539 | L58: =J58/'HUMAN RESOURCES'!I58 -> 0.18135593 | M58: =K58/'HUMAN RESOURCES'!I58 -> 0.0068176069 | N58: {=VLOOKUP(A58,'HUMAN RESOURCES'!$A$2:$M$2692,{2,3,4,5,6,7,8,9,10},0)} -> 0.011 | O58: 0.003 | P58: 71 | Q58: 66 | R58: 0.0303 | S58: 0.623 | T58: 0.073 | U58: 79060 | V58: 0.908 | W58: {=VLOOKUP(A58,TOURISM!$A$2:$F$2692,{3,6},0)} -> 680000000 | X58: 448000000 | Y58: =X58/'HUMAN RESOURCES'!I58 -> 5666.5823 | Z58: {=VLOOKUP(A58,BUSINESS!$A$2:$J$2692,{4,5,6,7,8,9},0)} -> 0.489 | AA58: 26 | AB58: 94 | AC58: 302 | AD58: 0.268 | AE58: 0.738
A59: =CONCAT(B59,C59) -> Andorra-Europe2005 | B59: Andorra-Europe | C59: 2005 | D59: Europe | E59: 2322163502 | F59: =E59/'HUMAN RESOURCES'!I59 -> 28589.975 | G59: 0.057 | H59: 2193 | I59: 0.148 | J59: {=VLOOKUP(A59,ENERGY!$A$2:$F$2692,{5,6},0)} -> 14338 | K59: 539 | L59: =J59/'HUMAN RESOURCES'!I59 -> 0.17652635 | M59: =K59/'HUMAN RESOURCES'!I59 -> 0.0066360514 | N59: {=VLOOKUP(A59,'HUMAN RESOURCES'!$A$2:$M$2692,{2,3,4,5,6,7,8,9,10},0)} -> 0.011 | O59: 0.003 | P59: 71 | Q59: 66 | R59: 0.0303 | S59: 0.623 | T59: 0.073 | U59: 81223 | V59: 0.903 | W59: {=VLOOKUP(A59,TOURISM!$A$2:$F$2692,{3,6},0)} -> 680000000 | X59: 448000000 | Y59: =X59/'HUMAN RESOURCES'!I59 -> 5515.6791 | Z59: {=VLOOKUP(A59,BUSINESS!$A$2:$J$2692,{4,5,6,7,8,9},0)} -> 0.489 | AA59: 26 | AB59: 94 | AC59: 302 | AD59: 0.376 | AE59: 0.795
A60: =CONCAT(B60,C60) -> Andorra-Europe2006 | B60: Andorra-Europe | C60: 2006 | D60: Europe | E60: 2539759286 | F60: =E60/'HUMAN RESOURCES'!I60 -> 31019.203 | G60: 0.058 | H60: 2356 | I60: 0.148 | J60: {=VLOOKUP(A60,ENERGY!$A$2:$F$2692,{5,6},0)} -> 14338 | K60: 576 | L60: =J60/'HUMAN RESOURCES'!I60 -> 0.17511633 | M60: =K60/'HUMAN RESOURCES'!I60 -> 0.0070349427 | N60: {=VLOOKUP(A60,'HUMAN RESOURCES'!$A$2:$M$2692,{2,3,4,5,6,7,8,9,10},0)} -> 0.011 | O60: 0.003 | P60: 71 | Q60: 66 | R60: 0.0303 | S60: 0.623 | T60: 0.073 | U60: 81877 | V60: 0.898 | W60: {=VLOOKUP(A60,TOURISM!$A$2:$F$2692,{3,6},0)} -> 680000000 | X60: 448000000 | Y60: =X60/'HUMAN RESOURCES'!I60 -> 5471.6221 | Z60: {=VLOOKUP(A60,BUSINESS!$A$2:$J$2692,{4,5,6,7,8,9},0)} -> 0.489 | AA60: 26 | AB60: 94 | AC60: 302 | AD60: 0.489 | AE60: 0.843
A61: =CONCAT(B61,C61) -> Andorra-Europe2007 | B61: Andorra-Europe | C61: 2007 | D61: Europe | E61: 2823503853 | F61: =E61/'HUMAN RESOURCES'!I61 -> 34732.862 | G61: 0.06 | H61: 2631 | I61: 0.148 | J61: {=VLOOKUP(A61,ENERGY!$A$2:$F$2692,{5,6},0)} -> 14338 | K61: 535 | L61: =J61/'HUMAN RESOURCES'!I61 -> 0.17637652 | M61: =K61/'HUMAN RESOURCES'!I61 -> 0.0065812134 | N61: {=VLOOKUP(A61,'HUMAN RESOURCES'!$A$2:$M$2692,{2,3,4,5,6,7,8,9,10},0)} -> 0.01 | O61: 0.003 | P61: 71 | Q61: 66 | R61: 0.0303 | S61: 0.623 | T61: 0.073 | U61: 81292 | V61: 0.894 | W61: {=VLOOKUP(A61,TOURISM!$A$2:$F$2692,{3,6},0)} -> 680000000 | X61: 448000000 | Y61: =X61/'HUMAN RESOURCES'!I61 -> 5510.9974 | Z61: {=VLOOKUP(A61,BUSINESS!$A$2:$J$2692,{4,5,6,7,8,9},0)} -> 0.489 | AA61: 26 | AB61: 94 | AC61: 302 | AD61: 0.709 | AE61: 0.781
A62: =CONCAT(B62,C62) -> Andorra-Europe2008 | B62: Andorra-Europe | C62: 2008 | D62: Europe | E62: 3245411584 | F62: =E62/'HUMAN RESOURCES'!I62 -> 40583.371 | G62: 0.062 | H62: 3012 | I62: 0.148 | J62: {=VLOOKUP(A62,ENERGY!$A$2:$F$2692,{5,6},0)} -> 14338 | K62: 524 | L62: =J62/'HUMAN RESOURCES'!I62 -> 0.17929448 | M62: =K62/'HUMAN RESOURCES'!I62 -> 0.0065525391 | N62: {=VLOOKUP(A62,'HUMAN RESOURCES'!$A$2:$M$2692,{2,3,4,5,6,7,8,9,10},0)} -> 0.01 | O62: 0.003 | P62: 71 | Q62: 66 | R62: 0.0303 | S62: 0.623 | T62: 0.073 | U62: 79969 | V62: 0.889 | W62: {=VLOOKUP(A62,TOURISM!$A$2:$F$2692,{3,6},0)} -> 680000000 | X62: 448000000 | Y62: =X62/'HUMAN RESOURCES'!I62 -> 5602.1708 | Z62: {=VLOOKUP(A62,BUSINESS!$A$2:$J$2692,{4,5,6,7,8,9},0)} -> 0.489 | AA62: 26 | AB62: 94 | AC62: 302 | AD62: 0.7 | AE62: 0.803
A63: =CONCAT(B63,C63) -> Andorra-Europe2009 | B63: Andorra-Europe | C63: 2009 | D63: Europe | E63: 3712034267 | F63: =E63/'HUMAN RESOURCES'!I63 -> 47191.475 | G63: 0.062 | H63: 3105 | I63: 0.148 | J63: {=VLOOKUP(A63,ENERGY!$A$2:$F$2692,{5,6},0)} -> 14338 | K63: 546 | L63: =J63/'HUMAN RESOURCES'!I63 -> 0.18228048 | M63: =K63/'HUMAN RESOURCES'!I63 -> 0.0069413545 | N63: {=VLOOKUP(A63,'HUMAN RESOURCES'!$A$2:$M$2692,{2,3,4,5,6,7,8,9,10},0)} -> 0.01 | O63: 0.003 | P63: 71 | Q63: 66 | R63: 0.0303 | S63: 0.623 | T63: 0.073 | U63: 78659 | V63: 0.884 | W63: {=VLOOKUP(A63,TOURISM!$A$2:$F$2692,{3,6},0)} -> 680000000 | X63: 448000000 | Y63: =X63/'HUMAN RESOURCES'!I63 -> 5695.4703 | Z63: {=VLOOKUP(A63,BUSINESS!$A$2:$J$2692,{4,5,6,7,8,9},0)} -> 0.489 | AA63: 26 | AB63: 94 | AC63: 302 | AD63: 0.785 | AE63: 0.821
A64: =CONCAT(B64,C64) -> Andorra-Europe2010 | B64: Andorra-Europe | C64: 2010 | D64: Europe | E64: 3712034267 | F64: =E64/'HUMAN RESOURCES'!I64 -> 47646.993 | G64: 0.062 | H64: 2762 | I64: 0.148 | J64: {=VLOOKUP(A64,ENERGY!$A$2:$F$2692,{5,6},0)} -> 14338 | K64: 565 | L64: =J64/'HUMAN RESOURCES'!I64 -> 0.18403995 | M64: =K64/'HUMAN RESOURCES'!I64 -> 0.0072522366 | N64: {=VLOOKUP(A64,'HUMAN RESOURCES'!$A$2:$M$2692,{2,3,4,5,6,7,8,9,10},0)} -> 0.01 | O64: 0.002 | P64: 71 | Q64: 66 | R64: 0.0303 | S64: 0.623 | T64: 0.073 | U64: 77907 | V64: 0.878 | W64: {=VLOOKUP(A64,TOURISM!$A$2:$F$2692,{3,6},0)} -> 680000000 | X64: 448000000 | Y64: =X64/'HUMAN RESOURCES'!I64 -> 5750.446 | Z64: {=VLOOKUP(A64,BUSINESS!$A$2:$J$2692,{4,5,6,7,8,9},0)} -> 0.489 | AA64: 26 | AB64: 94 | AC64: 302 | AD64: 0.81 | AE64: 0.841
A65: =CONCAT(B65,C65) -> Andorra-Europe2011 | B65: Andorra-Europe | C65: 2011 | D65: Europe | F65: =E65/'HUMAN RESOURCES'!I65 -> 0 | G65: 0.072 | H65: 2958 | I65: 0.148 | J65: {=VLOOKUP(A65,ENERGY!$A$2:$F$2692,{5,6},0)} -> 14338 | K65: 524 | L65: =J65/'HUMAN RESOURCES'!I65 -> 0.18413922 | M65: =K65/'HUMAN RESOURCES'!I65 -> 0.0067295961 | N65: {=VLOOKUP(A65,'HUMAN RESOURCES'!$A$2:$M$2692,{2,3,4,5,6,7,8,9,10},0)} -> 0.022763997 | O65: 0.002 | P65: 71 | Q65: 66 | R65: 0.0303 | S65: 0.623 | T65: 0.073 | U65: 77865 | V65: 0.873 | W65: {=VLOOKUP(A65,TOURISM!$A$2:$F$2692,{3,6},0)} -> 680000000 | X65: 448000000 | Y65: =X65/'HUMAN RESOURCES'!I65 -> 5753.5478 | Z65: {=VLOOKUP(A65,BUSINESS!$A$2:$J$2692,{4,5,6,7,8,9},0)} -> 0.489 | AA65: 26 | AB65: 94 | AC65: 302 | AD65: 0.81 | AE65: 0.835
A66: =CONCAT(B66,C66) -> Andorra-Europe2012 | B66: Andorra-Europe | C66: 2012 | D66: Europe | F66: =E66/'HUMAN RESOURCES'!I66 -> 0 | G66: 0.072 | H66: 3053 | I66: 0.148 | J66: {=VLOOKUP(A66,ENERGY!$A$2:$F$2692,{5,6},0)} -> 14338 | K66: 532 | L66: =J66/'HUMAN RESOURCES'!I66 -> 0.18297601 | M66: =K66/'HUMAN RESOURCES'!I66 -> 0.0067891782 | N66: {=VLOOKUP(A66,'HUMAN RESOURCES'!$A$2:$M$2692,{2,3,4,5,6,7,8,9,10},0)} -> 0.01 | O66: 0.002 | P66: 71 | Q66: 66 | R66: 0.0303 | S66: 0.623 | T66: 0.073 | U66: 78360 | V66: 0.867 | W66: {=VLOOKUP(A66,TOURISM!$A$2:$F$2692,{3,6},0)} -> 680000000 | X66: 448000000 | Y66: =X66/'HUMAN RESOURCES'!I66 -> 5717.2027 | Z66: {=VLOOKUP(A66,BUSINESS!$A$2:$J$2692,{4,5,6,7,8,9},0)} -> 0.489 | AA66: 26 | AB66: 94 | AC66: 302 | AD66: 0.864 | AE66: 0.815
...

Sheet GDP
A1: ID | B1: Country/Region | C1: YEAR | D1: Region | E1: GDP | F1: Health Exp % GDP | G1: Health Exp/Capita | H1: Lending Interest | I1: gdp updated
A2: =CONCAT(B2,C2) -> Afghanistan-Asia2000 | B2: Afghanistan-Asia | C2: 2000 | D2: Asia | F2: 0.064 | G2: 193 | H2: 0.148 | K2: Average | L2: Median | M2: S.D
A3: =CONCAT(B3,C3) -> Afghanistan-Asia2001 | B3: Afghanistan-Asia | C3: 2001 | D3: Asia | E3: 2461666315 | F3: 0.064 | G3: 193 | H3: 0.148 | I3: =IF(AND(E3="",B3=B2),E2,E3) -> 2461666315 | J3: healthEXP% | K3: =AVERAGE(F2:F2693) -> 0.064150873 | L3: =MEDIAN(F2:F2693) -> 0.064 | M3: =STDEV(F2:F2693) -> 0.024834117 | N3: S.D<mean replace missing values with mean
A4: =CONCAT(B4,C4) -> Afghanistan-Asia2002 | B4: Afghanistan-Asia | C4: 2002 | D4: Asia | E4: 4128818043 | F4: 0.089 | G4: 14 | H4: 0.148 | I4: =IF(AND(E4="",B4=B3),E3,E4) -> 4128818043 | J4: Health Exp/Capita | K4: =AVERAGE(G3:G2693) -> 734.67695 | L4: =MEDIAN(G3:G2693) -> 193 | M4: =STDEV(G3:G2693) -> 1403.2198 | N4: S.D>mean replace missing values with median
A5: =CONCAT(B5,C5) -> Afghanistan-Asia2003 | B5: Afghanistan-Asia | C5: 2003 | D5: Asia | E5: 4583648922 | F5: 0.1 | G5: 18 | H5: 0.148 | I5: =IF(AND(E5="",B5=B4),E4,E5) -> 4583648922 | J5: lending Interest | K5: =AVERAGE(H3:H2693) -> 0.14807175 | L5: =MEDIAN(H3:H2693) -> 0.148 | M5: =STDEV(H3:H2693) -> 0.14363646 | N5: S.D<mean replace missing values with mean
A6: =CONCAT(B6,C6) -> Afghanistan-Asia2004 | B6: Afghanistan-Asia | C6: 2004 | D6: Asia | E6: 5285461999 | F6: 0.098 | G6: 19 | H6: 0.148 | I6: =IF(AND(E6="",B6=B5),E5,E6) -> 5285461999
A7: =CONCAT(B7,C7) -> Afghanistan-Asia2005 | B7: Afghanistan-Asia | C7: 2005 | D7: Asia | E7: 6275076016 | F7: 0.092 | G7: 21 | H7: 0.148 | I7: =IF(AND(E7="",B7=B6),E6,E7) -> 6275076016
A8: =CONCAT(B8,C8) -> Afghanistan-Asia2006 | B8: Afghanistan-Asia | C8: 2006 | D8: Asia | E8: 7057597615 | F8: 0.091 | G8: 23 | H8: 0.18 | I8: =IF(AND(E8="",B8=B7),E7,E8) -> 7057597615
A9: =CONCAT(B9,C9) -> Afghanistan-Asia2007 | B9: Afghanistan-Asia | C9: 2007 | D9: Asia | E9: 9843851009 | F9: 0.1 | G9: 30 | H9: 0.181 | I9: =IF(AND(E9="",B9=B8),E8,E9) -> 9843851009
A10: =CONCAT(B10,C10) -> Afghanistan-Asia2008 | B10: Afghanistan-Asia | C10: 2008 | D10: Asia | E10: 10190534636 | F10: 0.097 | G10: 35 | H10: 0.149 | I10: =IF(AND(E10="",B10=B9),E9,E10) -> 10190534636
A11: =CONCAT(B11,C11) -> Afghanistan-Asia2009 | B11: Afghanistan-Asia | C11: 2009 | D11: Asia | E11: 12486950469 | F11: 0.087 | G11: 35 | H11: 0.15 | I11: =IF(AND(E11="",B11=B10),E10,E11) -> 12486950469
A12: =CONCAT(B12,C12) -> Afghanistan-Asia2010 | B12: Afghanistan-Asia | C12: 2010 | D12: Asia | E12: 15936784436 | F12: 0.087 | G12: 43 | H12: 0.157 | I12: =IF(AND(E12="",B12=B11),E11,E12) -> 15936784436
A13: =CONCAT(B13,C13) -> Afghanistan-Asia2011 | B13: Afghanistan-Asia | C13: 2011 | D13: Asia | E13: 17870159082 | F13: 0.084 | G13: 48 | H13: 0.151 | I13: =IF(AND(E13="",B13=B12),E12,E13) -> 17870159082
A14: =CONCAT(B14,C14) -> Afghanistan-Asia2012 | B14: Afghanistan-Asia | C14: 2012 | D14: Asia | E14: 20506795254 | F14: 0.086 | G14: 51 | H14: 0.15 | I14: =IF(AND(E14="",B14=B13),E13,E14) -> 20506795254
A15: =CONCAT(B15,C15) -> Albania-Europe2000 | B15: Albania-Europe | C15: 2000 | D15: Europe | E15: 3686649387 | F15: 0.064 | G15: 70 | H15: 0.221 | I15: =IF(AND(E15="",B15=B14),E14,E15) -> 3686649387
A16: =CONCAT(B16,C16) -> Albania-Europe2001 | B16: Albania-Europe | C16: 2001 | D16: Europe | E16: 4091020249 | F16: 0.06 | G16: 75 | H16: 0.197 | I16: =IF(AND(E16="",B16=B15),E15,E16) -> 4091020249
A17: =CONCAT(B17,C17) -> Albania-Europe2002 | B17: Albania-Europe | C17: 2002 | D17: Europe | E17: 4449373456 | F17: 0.065 | G17: 89 | H17: 0.153 | I17: =IF(AND(E17="",B17=B16),E16,E17) -> 4449373456
... A40: =CONCAT(B40,C40) -> Algeria-Africa2012 | B40: Algeria-Africa | C40: 2012 | D40: Africa | E40: 204000000000 | F40: 0.052 | G40: 279 | H40: 0.08 | I40: =IF(AND(E40="",B40=B39),E39,E40) -> 204000000000
A41: =CONCAT(B41,C41) -> American Samoa-Oceania2000 | B41: American Samoa-Oceania | C41: 2000 | D41: Oceania | F41: 0.064 | G41: 193 | H41: 0.148 | I41: =IF(AND(E41="",B41=B40),E40,E41)
A42: =CONCAT(B42,C42) -> American Samoa-Oceania2001 | B42: American Samoa-Oceania | C42: 2001 | D42: Oceania | F42: 0.064 | G42: 193 | H42: 0.148 | I42: =IF(AND(E42="",B42=B41),E41,E42)
A43: =CONCAT(B43,C43) -> American Samoa-Oceania2002 | B43: American Samoa-Oceania | C43: 2002 | D43: Oceania | F43: 0.064 | G43: 193 | H43: 0.148 | I43: =IF(AND(E43="",B43=B42),E42,E43)
A44: =CONCAT(B44,C44) -> American Samoa-Oceania2003 | B44: American Samoa-Oceania | C44: 2003 | D44: Oceania | F44: 0.064 | G44: 193 | H44: 0.148 | I44: =IF(AND(E44="",B44=B43),E43,E44)
A45: =CONCAT(B45,C45) -> American Samoa-Oceania2004 | B45: American Samoa-Oceania | C45: 2004 | D45: Oceania | F45: 0.064 | G45: 193 | H45: 0.148 | I45: =IF(AND(E45="",B45=B44),E44,E45)
A46: =CONCAT(B46,C46) -> American Samoa-Oceania2005 | B46: American Samoa-Oceania | C46: 2005 | D46: Oceania | F46: 0.064 | G46: 193 | H46: 0.148 | I46: =IF(AND(E46="",B46=B45),E45,E46)
A47: =CONCAT(B47,C47) -> American Samoa-Oceania2006 | B47: American Samoa-Oceania | C47: 2006 | D47: Oceania | F47: 0.064 | G47: 193 | H47: 0.148 | I47: =IF(AND(E47="",B47=B46),E46,E47)
A48: =CONCAT(B48,C48) -> American Samoa-Oceania2007 | B48: American Samoa-Oceania | C48: 2007 | D48: Oceania | F48: 0.064 | G48: 193 | H48: 0.148 | I48: =IF(AND(E48="",B48=B47),E47,E48)
A49: =CONCAT(B49,C49) -> American Samoa-Oceania2008 | B49: American Samoa-Oceania | C49: 2008 | D49: Oceania | F49: 0.064 | G49: 193 | H49: 0.148 | I49: =IF(AND(E49="",B49=B48),E48,E49)
A50: =CONCAT(B50,C50) -> American Samoa-Oceania2009 | B50: American Samoa-Oceania | C50: 2009 | D50: Oceania | F50: 0.064 | G50: 193 | H50: 0.148 | I50: =IF(AND(E50="",B50=B49),E49,E50)
A51: =CONCAT(B51,C51) -> American Samoa-Oceania2010 | B51: American Samoa-Oceania | C51: 2010 | D51: Oceania | F51: 0.064 | G51: 193 | H51: 0.148 | I51: =IF(AND(E51="",B51=B50),E50,E51)
A52: =CONCAT(B52,C52) -> American Samoa-Oceania2011 | B52: American Samoa-Oceania | C52: 2011 | D52: Oceania | F52: 0.064 | G52: 193 | H52: 0.148 | I52: =IF(AND(E52="",B52=B51),E51,E52)
... A54: =CONCAT(B54,C54) -> Andorra-Europe2000 | B54: Andorra-Europe | C54: 2000 | D54: Europe | F54: 0.083 | G54: 3057 | H54: 0.148 | I54: =IF(AND(E54="",B54=B53),E53,E54)
A55: =CONCAT(B55,C55) -> Andorra-Europe2001 | B55: Andorra-Europe | C55: 2001 | D55: Europe | E55: 1133644295 | F55: 0.062 | G55: 1330 | H55: 0.148 | I55: =IF(AND(E55="",B55=B54),E54,E55) -> 1133644295
A56: =CONCAT(B56,C56) -> Andorra-Europe2002 | B56: Andorra-Europe | C56: 2002 | D56: Europe | E56: 1264760246 | F56: 0.056 | G56: 1294 | H56: 0.148 | I56: =IF(AND(E56="",B56=B55),E55,E56) -> 1264760246
A57: =CONCAT(B57,C57) -> Andorra-Europe2003 | B57: Andorra-Europe | C57: 2003 | D57: Europe | E57: 1456198796 | F57: 0.058 | G57: 1486 | H57: 0.148 | I57: =IF(AND(E57="",B57=B56),E56,E57) -> 1456198796
A58: =CONCAT(B58,C58) -> Andorra-Europe2004 | B58: Andorra-Europe | C58: 2004 | D58: Europe | E58: 1917948475 | F58: 0.058 | G58: 1891 | H58: 0.148 | I58: =IF(AND(E58="",B58=B57),E57,E58) -> 1917948475
A59: =CONCAT(B59,C59) -> Andorra-Europe2005 | B59: Andorra-Europe | C59: 2005 | D59: Europe | E59: 2322163502 | F59: 0.057 | G59: 2193 | H59: 0.148 | I59: =IF(AND(E59="",B59=B58),E58,E59) -> 2322163502
A60: =CONCAT(B60,C60) -> Andorra-Europe2006 | B60: Andorra-Europe | C60: 2006 | D60: Europe | E60: 2539759286 | F60: 0.058 | G60: 2356 | H60: 0.148 | I60: =IF(AND(E60="",B60=B59),E59,E60) -> 2539759286
A61: =CONCAT(B61,C61) -> Andorra-Europe2007 | B61: Andorra-Europe | C61: 2007 | D61: Europe | E61: 2823503853 | F61: 0.06 | G61: 2631 | H61: 0.148 | I61: =IF(AND(E61="",B61=B60),E60,E61) -> 2823503853
A62: =CONCAT(B62,C62) -> Andorra-Europe2008 | B62: Andorra-Europe | C62: 2008 | D62: Europe | E62: 3245411584 | F62: 0.062 | G62: 3012 | H62: 0.148 | I62: =IF(AND(E62="",B62=B61),E61,E62) -> 3245411584
A63: =CONCAT(B63,C63) -> Andorra-Europe2009 | B63: Andorra-Europe | C63: 2009 | D63: Europe | E63: 3712034267 | F63: 0.062 | G63: 3105 | H63: 0.148 | I63: =IF(AND(E63="",B63=B62),E62,E63) -> 3712034267
...

Sheet ENERGY
A1: ID | B1: Region | C1: Country/Region | D1: YEAR | E1: Energy Usage | F1: CO2 Emissions
A2: =CONCAT(C2,D2) -> Afghanistan-Asia2000 | B2: Asia | C2: Afghanistan-Asia | D2: 2000 | E2: 14338 | F2: 8529
A3: =CONCAT(C3,D3) -> Afghanistan-Asia2001 | B3: Asia | C3: Afghanistan-Asia | D3: 2001 | E3: 14338 | F3: 8529
A4: =CONCAT(C4,D4) -> Afghanistan-Asia2002 | B4: Asia | C4: Afghanistan-Asia | D4: 2002 | E4: 14338 | F4: 8236
A5: =CONCAT(C5,D5) -> Afghanistan-Asia2003 | B5: Asia | C5: Afghanistan-Asia | D5: 2003 | E5: 14338 | F5: 6524
A6: =CONCAT(C6,D6) -> Afghanistan-Asia2004 | B6: Asia | C6: Afghanistan-Asia | D6: 2004 | E6: 14338 | F6: 3927
A7: =CONCAT(C7,D7) -> Afghanistan-Asia2005 | B7: Asia | C7: Afghanistan-Asia | D7: 2005 | E7: 14338 | F7: 1991
A8: =CONCAT(C8,D8) -> Afghanistan-Asia2006 | B8: Asia | C8: Afghanistan-Asia | D8: 2006 | E8: 14338 | F8: 1016
A9: =CONCAT(C9,D9) -> Afghanistan-Asia2007 | B9: Asia | C9: Afghanistan-Asia | D9: 2007 | E9: 14338 | F9: 583
A10: =CONCAT(C10,D10) -> Afghanistan-Asia2008 | B10: Asia | C10: Afghanistan-Asia | D10: 2008 | E10: 14338 | F10: 781
A11: =CONCAT(C11,D11) -> Afghanistan-Asia2009 | B11: Asia | C11: Afghanistan-Asia | D11: 2009 | E11: 14338 | F11: 1338
A12: =CONCAT(C12,D12) -> Afghanistan-Asia2010 | B12: Asia | C12: Afghanistan-Asia | D12: 2010 | E12: 14338 | F12: 733
A13: =CONCAT(C13,D13) -> Afghanistan-Asia2011 | B13: Asia | C13: Afghanistan-Asia | D13: 2011 | E13: 14338 | F13: 645
A14: =CONCAT(C14,D14) -> Afghanistan-Asia2012 | B14: Asia | C14: Afghanistan-Asia | D14: 2012 | E14: 14338 | F14: 359
A15: =CONCAT(C15,D15) -> Albania-Europe2000 | B15: Europe | C15: Albania-Europe | D15: 2000 | E15: 14338 | F15: 8529 | H15: Average | I15: Median | J15: S.D
A16: =CONCAT(C16,D16) -> Albania-Europe2001 | B16: Europe | C16: Albania-Europe | D16: 2001 | E16: 2173 | F16: 8529 | G16: Energy Usage | H16: =AVERAGE(E26:E2715) -> 56481.71 | I16: =MEDIAN(E26:E2715) -> 14338 | J16: =STDEV(E26:E2715) -> 214664.34 | K16: S.D>mean replace missing values with median
A17: =CONCAT(C17,D17) -> Albania-Europe2002 | B17: Europe | C17: Albania-Europe | D17: 2002 | E17: 2059 | F17: 4283 | G17: CO2 Emissions | H17: =AVERAGE(F38:F2727) -> 115345.84 | I17: =MEDIAN(F38:F2727) -> 8529 | J17: =STDEV(F38:F2727) -> 553618.55 | K17: S.D>mean replace missing values with median
A18: =CONCAT(C18,D18) -> Albania-Europe2003 | B18: Europe | C18: Albania-Europe | D18: 2003 | E18: 2068 | F18: 3880
A19: =CONCAT(C19,D19) -> Albania-Europe2004 | B19: Europe | C19: Albania-Europe | D19: 2004 | E19: 2061 | F19: 4129
A20: =CONCAT(C20,D20) -> Albania-Europe2005 | B20: Europe | C20: Albania-Europe | D20: 2005 | E20: 2025 | F20: 4056
A21: =CONCAT(C21,D21) -> Albania-Europe2006 | B21: Europe | C21: Albania-Europe | D21: 2006 | E21: 2172 | F21: 4254
A22: =CONCAT(C22,D22) -> Albania-Europe2007 | B22: Europe | C22: Albania-Europe | D22: 2007 | E22: 1976 | F22: 4294
A23: =CONCAT(C23,D23) -> Albania-Europe2008 | B23: Europe | C23: Albania-Europe | D23: 2008 | E23: 1763 | F23: 3022
A24: =CONCAT(C24,D24) -> Albania-Europe2009 | B24: Europe | C24: Albania-Europe | D24: 2009 | E24: 2068 | F24: 3865
A25: =CONCAT(C25,D25) -> Albania-Europe2010 | B25: Europe | C25: Albania-Europe | D25: 2010 | E25: 2172 | F25: 4166
A26: =CONCAT(C26,D26) -> Albania-Europe2011 | B26: Europe | C26: Albania-Europe | D26: 2011 | E26: 1783 | F26: 3223
A27: =CONCAT(C27,D27) -> Albania-Europe2012 | B27: Europe | C27: Albania-Europe | D27: 2012 | E27: 1975 | F27: 3751
A28: =CONCAT(C28,D28) -> Algeria-Africa2000 | B28: Africa | C28: Algeria-Africa | D28: 2000 | E28: 14338 | F28: 8529
A29: =CONCAT(C29,D29) -> Algeria-Africa2001 | B29: Africa | C29: Algeria-Africa | D29: 2001 | E29: 41852 | F29: 8529
... A2692: =CONCAT(C2692,D2692) -> Zimbabwe-Africa2012 | B2692: Africa | C2692: Zimbabwe-Africa | D2692: 2012 | E2692: 9865 | F2692: 13887

Sheet HUMAN RESOURCES
A1: ID | B1: Birth Rate | C1: Infant Mortality Rate | D1: Life Expectancy Female | E1: Life Expectancy Male | F1: Population 0-14 | G1: Population 15-64 | H1: Population 65+ | I1: Population Total | J1: Population Urban | K1: Country/Region | L1: Region | M1: YEAR
A2: =CONCATENATE(K2,M2) -> Afghanistan-Asia2000 | B2: 0.05 | C2: 0.095 | D2: 56 | E2: 54 | F2: 0.495 | G2: 0.485 | H2: 0.02 | I2: 20595360 | J2: 0.213 | K2: Afghanistan-Asia | L2: Asia | M2: 2000
A3: =CONCATENATE(K3,M3) -> Afghanistan-Asia2001 | B3: 0.049 | C3: 0.093 | D3: 56 | E3: 54 | F3: 0.495 | G3: 0.484 | H3: 0.02 | I3: 21347782 | J3: 0.216 | K3: Afghanistan-Asia | L3: Asia | M3: 2001
A4: =CONCATENATE(K4,M4) -> Afghanistan-Asia2002 | B4: 0.048 | C4: 0.091 | D4: 57 | E4: 55 | F4: 0.495 | G4: 0.485 | H4: 0.02 | I4: 22202806 | J4: 0.219 | K4: Afghanistan-Asia | L4: Asia | M4: 2002
A5: =CONCATENATE(K5,M5) -> Afghanistan-Asia2003 | B5: 0.047 | C5: 0.088 | D5: 57 | E5: 55 | F5: 0.494 | G5: 0.485 | H5: 0.02 | I5: 23116142 | J5: 0.222 | K5: Afghanistan-Asia | L5: Asia | M5: 2003
A6: =CONCATENATE(K6,M6) -> Afghanistan-Asia2004 | B6: 0.046 | C6: 0.086 | D6: 58 | E6: 55 | F6: 0.494 | G6: 0.486 | H6: 0.02 | I6: 24018682 | J6: 0.226 | K6: Afghanistan-Asia | L6: Asia | M6: 2004
A7: =CONCATENATE(K7,M7) -> Afghanistan-Asia2005 | B7: 0.045 | C7: 0.084 | D7: 58 | E7: 56 | F7: 0.493 | G7: 0.487 | H7: 0.02 | I7: 24860855 | J7: 0.229 | K7: Afghanistan-Asia | L7: Asia | M7: 2005
A8: =CONCATENATE(K8,M8) -> Afghanistan-Asia2006 | B8: 0.044 | C8: 0.082 | D8: 59 | E8: 56 | F8: 0.493 | G8: 0.487 | H8: 0.02 | I8: 25631282 | J8: 0.232 | K8: Afghanistan-Asia | L8: Asia | M8: 2006
A9: =CONCATENATE(K9,M9) -> Afghanistan-Asia2007 | B9: 0.042 | C9: 0.08 | D9: 59 | E9: 57 | F9: 0.492 | G9: 0.487 | H9: 0.021 | I9: 26349243 | J9: 0.236 | K9: Afghanistan-Asia | L9: Asia | M9: 2007
A10: =CONCATENATE(K10,M10) -> Afghanistan-Asia2008 | B10: 0.041 | C10: 0.079 | D10: 60 | E10: 57 | F10: 0.492 | G10: 0.487 | H10: 0.021 | I10: 27032197 | J10: 0.239 | K10: Afghanistan-Asia | L10: Asia | M10: 2008
A11: =CONCATENATE(K11,M11) -> Afghanistan-Asia2009 | B11: 0.039 | C11: 0.077 | D11: 60 | E11: 58 | F11: 0.49 | G11: 0.489 | H11: 0.021 | I11: 27708187 | J11: 0.243 | K11: Afghanistan-Asia | L11: Asia | M11: 2009
A12: =CONCATENATE(K12,M12) -> Afghanistan-Asia2010 | B12: 0.038 | C12: 0.075 | D12: 61 | E12: 58 | F12: 0.486 | G12: 0.492 | H12: 0.022 | I12: 28397812 | J12: 0.247 | K12: Afghanistan-Asia | L12: Asia | M12: 2010
A13: =CONCATENATE(K13,M13) -> Afghanistan-Asia2011 | B13: 0.037 | C13: 0.074 | D13: 61 | E13: 59 | F13: 0.481 | G13: 0.497 | H13: 0.022 | I13: 29105480 | J13: 0.251 | K13: Afghanistan-Asia | L13: Asia | M13: 2011
... A27: =CONCATENATE(K27,M27) -> Albania-Europe2012 | B27: 0.013 | C27: 0.014 | D27: 80 | E27: 74 | F27: 0.213 | G27: 0.681 | H27: 0.106 | I27: 2801681 | J27: 0.543 | K27: Albania-Europe | L27: Europe | M27: 2012
A28: =CONCATENATE(K28,M28) -> Algeria-Africa2000 | B28: 0.02 | C28: 0.034 | D28: 71 | E28: 67 | F28: 0.342 | G28: 0.619 | H28: 0.039 | I28: 31719449 | J28: 0.599 | K28: Algeria-Africa | L28: Africa | M28: 2000 | P28: Average | Q28: Median | R28: S.D
A29: =CONCATENATE(K29,M29) -> Algeria-Africa2001 | B29: 0.019 | C29: 0.033 | D29: 71 | E29: 68 | F29: 0.33 | G29: 0.63 | H29: 0.04 | I29: 32150198 | J29: 0.607 | K29: Algeria-Africa | L29: Africa | M29: 2001
A30: =CONCATENATE(K30,M30) -> Algeria-Africa2002 | B30: 0.019 | C30: 0.032 | D30: 71 | E30: 68 | F30: 0.318 | G30: 0.641 | H30: 0.041 | I30: 32572977 | J30: 0.615 | K30: Algeria-Africa | L30: Africa | M30: 2002
A31: =CONCATENATE(K31,M31) -> Algeria-Africa2003 | B31: 0.02 | C31: 0.031 | D31: 71 | E31: 68 | F31: 0.307 | G31: 0.651 | H31: 0.042 | I31: 33003442 | J31: 0.623 | K31: Algeria-Africa | L31: Africa | M31: 2003
A32: =CONCATENATE(K32,M32) -> Algeria-Africa2004 | B32: 0.02 | C32: 0.03 | D32: 71 | E32: 68 | F32: 0.297 | G32: 0.66 | H32: 0.043 | I32: 33461345 | J32: 0.631 | K32: Algeria-Africa | L32: Africa | M32: 2004
A33: =CONCATENATE(K33,M33) -> Algeria-Africa2005 | B33: 0.021 | C33: 0.029 | D33: 71 | E33: 68 | F33: 0.289 | G33: 0.667 | H33: 0.044 | I33: 33960903 | J33: 0.638 | K33: Algeria-Africa | L33: Africa | M33: 2005
A34: =CONCATENATE(K34,M34) -> Algeria-Africa2006 | B34: 0.022 | C34: 0.028 | D34: 72 | E34: 68 | F34: 0.282 | G34: 0.673 | H34: 0.045 | I34: 34507214 | J34: 0.646 | K34: Algeria-Africa | L34: Africa | M34: 2006
A35: =CONCATENATE(K35,M35) -> Algeria-Africa2007 | B35: 0.023 | C35: 0.026 | D35: 72 | E35: 69 | F35: 0.277 | G35: 0.677 | H35: 0.046 | I35: 35097043 | J35: 0.653 | K35: Algeria-Africa | L35: Africa | M35: 2007
A36: =CONCATENATE(K36,M36) -> Algeria-Africa2008 | B36: 0.024 | C36: 0.025 | D36: 72 | E36: 69 | F36: 0.274 | G36: 0.68 | H36: 0.047 | I36: 35725377 | J36: 0.661 | K36: Algeria-Africa | L36: Africa | M36: 2008
A37: =CONCATENATE(K37,M37) -> Algeria-Africa2009 | B37: 0.024 | C37: 0.024 | D37: 72 | E37: 69 | F37: 0.272 | G37: 0.681 | H37: 0.047 | I37: 36383302 | J37: 0.668 | K37: Algeria-Africa | L37: Africa | M37: 2009
A38: =CONCATENATE(K38,M38) -> Algeria-Africa2010 | B38: 0.025 | C38: 0.024 | D38: 72 | E38: 69 | F38: 0.271 | G38: 0.681 | H38: 0.047 | I38: 37062820 | J38: 0.675 | K38: Algeria-Africa | L38: Africa | M38: 2010
A39: =CONCATENATE(K39,M39) -> Algeria-Africa2011 | B39: 0.025 | C39: 0.023 | D39: 72 | E39: 69 | F39: 0.272 | G39: 0.681 | H39: 0.047 | I39: 37762962 | J39: 0.682 | K39: Algeria-Africa | L39: Africa | M39: 2011
A40: =CONCATENATE(K40,M40) -> Algeria-Africa2012 | B40: 0.025 | C40: 0.022 | D40: 73 | E40: 69 | F40: 0.274 | G40: 0.679 | H40: 0.047 | I40: 38481705 | J40: 0.689 | K40: Algeria-Africa | L40: Africa | M40: 2012
... A66: =CONCATENATE(K66,M66) -> Andorra-Europe2012 | B66: 0.01 | C66: 0.002 | D66: 71 | E66: 66 | F66: 0.0303 | G66: 0.623 | H66: 0.073 | I66: 78360 | J66: 0.867 | K66: Andorra-Europe | L66: Europe | M66: 2012
A67: =CONCATENATE(K67,M67) -> Angola-Africa2000 | B67: 0.05 | C67: 0.128 | D67: 47 | E67: 44 | F67: 0.476 | G67: 0.499 | H67: 0.025 | I67: 13924930 | J67: 0.324 | K67: Angola-Africa | L67: Africa | M67: 2000 | O67: Birth Rate | P67: =AVERAGE(B66:B2756) -> 0.022758945 | Q67: =MEDIAN(B66:B2756) -> 0.021 | R67: =STDEV(B66:B2756) -> 0.011084308 | S67: replacing missing values with mean
A68: =CONCATENATE(K68,M68) -> Angola-Africa2001 | B68: 0.05 | C68: 0.127 | D68: 47 | E68: 45 | F68: 0.477 | G68: 0.499 | H68: 0.025 | I68: 14385283 | J68: 0.332 | K68: Angola-Africa | L68: Africa | M68: 2001
A69: =CONCATENATE(K69,M69) -> Angola-Africa2002 | B69: 0.05 | C69: 0.126 | D69: 48 | E69: 45 | F69: 0.477 | G69: 0.499 | H69: 0.025 | I69: 14886574 | J69: 0.339 | K69: Angola-Africa | L69: Africa | M69: 2002
A70: =CONCATENATE(K70,M70) -> Angola-Africa2003 | B70: 0.05 | C70: 0.125 | D70: 49 | E70: 46 | F70: 0.477 | G70: 0.498 | H70: 0.025 | I70: 15421075 | J70: 0.346 | K70: Angola-Africa | L70: Africa | M70: 2003
A71: =CONCATENATE(K71,M71) -> Angola-Africa2004 | B71: 0.05 | C71: 0.123 | D71: 49 | E71: 47 | F71: 0.477 | G71: 0.498 | H71: 0.025 | I71: 15976715 | J71: 0.354 | K71: Angola-Africa | L71: Africa | M71: 2004
A72: =CONCATENATE(K72,M72) -> Angola-Africa2005 | B72: 0.049 | C72: 0.122 | D72: 50 | E72: 47 | F72: 0.478 | G72: 0.498 | H72: 0.025 | I72: 16544376 | J72: 0.362 | K72: Angola-Africa | L72: Africa | M72: 2005
A73: =CONCATENATE(K73,M73) -> Angola-Africa2006 | B73: 0.049 | C73: 0.12 | D73: 50 | E73: 48 | F73: 0.478 | G73: 0.497 | H73: 0.024 | I73: 17122409 | J73: 0.369 | K73: Angola-Africa | L73: Africa | M73: 2006
A74: =CONCATENATE(K74,M74) -> Angola-Africa2007 | B74: 0.048 | C74: 0.117 | D74: 51 | E74: 48 | F74: 0.479 | G74: 0.497 | H74: 0.024 | I74: 17712824 | J74: 0.377 | K74: Angola-Africa | L74: Africa | M74: 2007
A75: =CONCATENATE(K75,M75) -> Angola-Africa2008 | B75: 0.048 | C75: 0.115 | D75: 51 | E75: 48 | F75: 0.479 | G75: 0.497 | H75: 0.024 | I75: 18314441 | J75: 0.385 | K75: Angola-Africa | L75: Africa | M75: 2008
A76: =CONCATENATE(K76,M76) -> Angola-Africa2009 | B76: 0.047 | C76: 0.112 | D76: 52 | E76: 49 | F76: 0.479 | G76: 0.497 | H76: 0.024 | I76: 18926650 | J76: 0.393 | K76: Angola-Africa | L76: Africa | M76: 2009
A77: =CONCATENATE(K77,M77) -> Angola-Africa2010 | B77: 0.046 | C77: 0.11 | D77: 52 | E77: 49 | F77: 0.478 | G77: 0.498 | H77: 0.024 | I77: 19549124 | J77: 0.401 | K77: Angola-Africa | L77: Africa | M77: 2010
A78: =CONCATENATE(K78,M78) -> Angola-Africa2011 | B78: 0.046 | C78: 0.107 | D78: 53 | E78: 50 | F78: 0.477 | G78: 0.499 | H78: 0.024 | I78: 20180490 | J78: 0.409 | K78: Angola-Africa | L78: Africa | M78: 2011
...

Sheet TOURISM
A1: ID | B1: Region | C1: Tourism Inbound | D1: Country/Region | E1: YEAR | F1: Tourism Outbound
A2: =CONCAT(D2,E2) -> Afghanistan-Asia2000 | B2: Asia | C2: 680000000 | D2: Afghanistan-Asia | E2: 2000 | F2: 448000000
A3: =CONCAT(D3,E3) -> Afghanistan-Asia2001 | B3: Asia | C3: 680000000 | D3: Afghanistan-Asia | E3: 2001 | F3: 448000000
A4: =CONCAT(D4,E4) -> Afghanistan-Asia2002 | B4: Asia | C4: 680000000 | D4: Afghanistan-Asia | E4: 2002 | F4: 448000000
A5: =CONCAT(D5,E5) -> Afghanistan-Asia2003 | B5: Asia | C5: 680000000 | D5: Afghanistan-Asia | E5: 2003 | F5: 448000000
A6: =CONCAT(D6,E6) -> Afghanistan-Asia2004 | B6: Asia | C6: 680000000 | D6: Afghanistan-Asia | E6: 2004 | F6: 448000000
A7: =CONCAT(D7,E7) -> Afghanistan-Asia2005 | B7: Asia | C7: 680000000 | D7: Afghanistan-Asia | E7: 2005 | F7: 448000000
A8: =CONCAT(D8,E8) -> Afghanistan-Asia2006 | B8: Asia | C8: 680000000 | D8: Afghanistan-Asia | E8: 2006 | F8: 448000000
A9: =CONCAT(D9,E9) -> Afghanistan-Asia2007 | B9: Asia | C9: 680000000 | D9: Afghanistan-Asia | E9: 2007 | F9: 448000000
A10: =CONCAT(D10,E10) -> Afghanistan-Asia2008 | B10: Asia | C10: 43000000 | D10: Afghanistan-Asia | E10: 2008 | F10: 58000000
A11: =CONCAT(D11,E11) -> Afghanistan-Asia2009 | B11: Asia | C11: 96000000 | D11: Afghanistan-Asia | E11: 2009 | F11: 61000000
A12: =CONCAT(D12,E12) -> Afghanistan-Asia2010 | B12: Asia | C12: 138000000 | D12: Afghanistan-Asia | E12: 2010 | F12: 86000000
A13: =CONCAT(D13,E13) -> Afghanistan-Asia2011 | B13: Asia | C13: 137000000 | D13: Afghanistan-Asia | E13: 2011 | F13: 127000000
... A27: =CONCAT(D27,E27) -> Albania-Europe2012 | B27: Europe | C27: 1623000000 | D27: Albania-Europe | E27: 2012 | F27: 1374000000
A28: =CONCAT(D28,E28) -> Algeria-Africa2000 | B28: Africa | C28: 102000000 | D28: Algeria-Africa | E28: 2000 | F28: 193000000 | I28: Average | J28: median | K28: S.D
A29: =CONCAT(D29,E29) -> Algeria-Africa2001 | B29: Africa | C29: 100000000 | D29: Algeria-Africa | E29: 2001 | F29: 194000000
A30: =CONCAT(D30,E30) -> Algeria-Africa2002 | B30: Africa | C30: 111000000 | D30: Algeria-Africa | E30: 2002 | F30: 248000000
A31: =CONCAT(D31,E31) -> Algeria-Africa2003 | B31: Africa | C31: 112000000 | D31: Algeria-Africa | E31: 2003 | F31: 255000000
A32: =CONCAT(D32,E32) -> Algeria-Africa2004 | B32: Africa | C32: 178000000 | D32: Algeria-Africa | E32: 2004 | F32: 341000000
A33: =CONCAT(D33,E33) -> Algeria-Africa2005 | B33: Africa | C33: 477000000 | D33: Algeria-Africa | E33: 2005 | F33: 660000000
A34: =CONCAT(D34,E34) -> Algeria-Africa2006 | B34: Africa | C34: 393000000 | D34: Algeria-Africa | E34: 2006 | F34: 414000000
